<robot name="test_robot">
    <link name="base_link">
        <collision>
            <geometry>
                <box size="0.05 0.030 0.020"/>
            </geometry>
        </collision>
         <visual>
            <geometry>
                <mesh filename="package://owi535/meshes/battery_pack.dae" />
            </geometry>
        </visual>
        <inertial>
            <origin xyz="0 0 0" rpy="0 0 0" />
            <mass value="1" />
            <inertia
              ixx="1.0" ixy="0.0" ixz="0.0"
              iyy="1.0" iyz="0.0"
              izz="1.0" />
        </inertial>
    </link>
    <link name="rotation_base">
        <visual>
            <geometry>
                <mesh filename="package://owi535/meshes/rotation_base.dae" />
            </geometry>
        </visual>
        <collision>
            <geometry>
                <box size="0.05 0.05 0.05"/>
            </geometry>
        </collision>
        <inertial>
            <origin xyz="0 0 0" rpy="0 0 0" />
            <mass value="0.1" />
            <inertia
              ixx="1.0" ixy="0.0" ixz="0.0"
              iyy="1.0" iyz="0.0"
              izz="1.0" />
        </inertial>
    </link>
    <joint name="rotator" type="fixed">
        <parent link="base_link" />
        <child link="rotation_base" />
        <origin xyz="0 0 0" rpy="0 0 0" />
    </joint>
    <link name="switchboard">
        <visual>
            <geometry>
                <mesh filename="package://owi535/meshes/switchboard.dae" />
            </geometry>
        </visual>
        <collision>
            <geometry>
                <box size="0.05 0.05 0.05"/>
            </geometry>
        </collision>
        <inertial>
            <origin xyz="0 0 0" rpy="0 0 0" />
            <mass value="0.1" />
            <inertia
              ixx="1.0" ixy="0.0" ixz="0.0"
              iyy="1.0" iyz="0.0"
              izz="1.0" />
        </inertial>
    </link>
    <joint name="switcher" type="fixed">
        <parent link="base_link" />
        <child link="switchboard" />
        <origin xyz="0.12 0 0.0500" rpy="0 0 0" />
    </joint>
    <link name="shoulder_motor">
        <visual>
            <geometry>
                <mesh filename="package://owi535/meshes/shoulder.dae" />
            </geometry>
        </visual>
        <collision>
            <geometry>
                <box size="0.05 0.05 0.05"/>
            </geometry>
        </collision>
        <inertial>
            <origin xyz="0 0 0" rpy="0 0 0" />
            <mass value="0.1" />
            <inertia
              ixx="1.0" ixy="0.0" ixz="0.0"
              iyy="1.0" iyz="0.0"
              izz="1.0" />
        </inertial>
    </link>
    <joint name="rotationbase" type="revolute">
        <parent link="base_link" />
        <child link="shoulder_motor" />
        <origin xyz="0 0 0.0580" rpy="0 0 0" />
        <axis xyz="0 0 1" />
        <limit lower="-2.57" upper="2.57" effort="3" velocity="1.178465545" />
    </joint>
    <link name="humerus_left">
        <visual>
            <geometry>
                <mesh filename="package://owi535/meshes/humerus_link.dae" />
            </geometry>
        </visual>
        <collision>
            <geometry>
                <box size="15 5 5"/>
            </geometry>
        </collision>
        <inertial>
            <origin xyz="0 0 0" rpy="0 0 0" />
            <mass value="0.1" />
            <inertia
              ixx="1.0" ixy="0.0" ixz="0.0"
              iyy="1.0" iyz="0.0"
              izz="1.0" />
        </inertial>
    </link>
    <joint name="shoulder" type="revolute">
        <parent link="shoulder_motor" />
        <child link="humerus_left" />
        <origin xyz="0 0.0233 0" rpy="0 0 0" />
        <axis xyz="0 1 0" />
        <limit lower="-1.57" upper="1.27" effort="3" velocity="1.178465545" />
    </joint>
    <link name="humerus_right">
        <visual>
            <geometry>
                <mesh filename="package://owi535/meshes/humerus_link.dae" />
            </geometry>
        </visual>
        <collision>
            <geometry>
                <box size="15 5 5"/>
            </geometry>
        </collision>
        <inertial>
            <origin xyz="0 0 0" rpy="0 0 0" />
            <mass value="0.1" />
            <inertia
              ixx="1.0" ixy="0.0" ixz="0.0"
              iyy="1.0" iyz="0.0"
              izz="1.0" />
        </inertial>
    </link>
    <joint name="humerus" type="fixed">
        <parent link="humerus_left" />
        <child link="humerus_right" />
        <origin xyz="0 -0.0466 0" rpy="0 0 3.14" />
    </joint>
    <link name="elbow_motor">
        <visual>
            <geometry>
                <mesh filename="package://owi535/meshes/shoulder.dae" />
            </geometry>
        </visual>
        <collision>
            <geometry>
                <box size="0.05 0.05 0.05"/>
            </geometry>
        </collision>
        <inertial>
            <origin xyz="0 0 0" rpy="0 0 0" />
            <mass value="0.1" />
            <inertia
              ixx="1.0" ixy="0.0" ixz="0.0"
              iyy="1.0" iyz="0.0"
              izz="1.0" />
        </inertial>
    </link>
    <joint name="elbow" type="revolute">
        <parent link="humerus_left" />
        <child link="elbow_motor" />
        <origin xyz="0 -0.0233 0.1010" rpy="0 0 0" />
        <axis xyz="0 1 0" />
        <limit lower="-1.00" upper="4.34" effort="3" velocity="1.178465545" />
    </joint>

    <link name="radius_link_down">
        <visual>
            <geometry>
                <mesh filename="package://owi535/meshes/radius_link.dae" />
            </geometry>
        </visual>
        <collision>
            <geometry>
                <box size="15 5 5"/>
            </geometry>
        </collision>
        <inertial>
            <origin xyz="0 0 0" rpy="0 0 0" />
            <mass value="0.1" />
            <inertia
              ixx="1.0" ixy="0.0" ixz="0.0"
              iyy="1.0" iyz="0.0"
              izz="1.0" />
        </inertial>
    </link>
    <joint name="lower_radius" type="fixed">
        <parent link="elbow_motor" />
        <child link="radius_link_down" />
        <origin xyz="0.01 0 -0.0155" rpy="0 0 0" />
    </joint>
    <link name="radius_link_up">
        <visual>
            <geometry>
                <mesh filename="package://owi535/meshes/radius_link.dae" />
            </geometry>
        </visual>
        <collision>
            <geometry>
                <box size="15 5 5"/>
            </geometry>
        </collision>
        <inertial>
            <origin xyz="0 0 0" rpy="0 0 0" />
            <mass value="0.1" />
            <inertia
              ixx="1.0" ixy="0.0" ixz="0.0"
              iyy="1.0" iyz="0.0"
              izz="1.0" />
        </inertial>
    </link>
    <joint name="upper_radius" type="fixed">
        <parent link="elbow_motor" />
        <child link="radius_link_up" />
        <origin xyz="0.01 0 0.0178" rpy="3.14 0 0" />
    </joint>
    <link name="wrist_motor">
        <visual>
            <geometry>
                <mesh filename="package://owi535/meshes/shoulder.dae" />
            </geometry>
        </visual>
        <collision>
            <geometry>
                <box size="0.05 0.05 0.05"/>
            </geometry>
        </collision>
        <inertial>
            <origin xyz="0 0 0" rpy="0 0 0" />
            <mass value="0.1" />
            <inertia
              ixx="1.0" ixy="0.0" ixz="0.0"
              iyy="1.0" iyz="0.0"
              izz="1.0" />
        </inertial>
    </link>
    <joint name="wrist_fixed" type="fixed">
        <parent link="elbow_motor" />
        <child link="wrist_motor" />
        <origin xyz="-0.0721 0 0" rpy="0 0 0" />
    </joint>
    <link name="wrist_base">
        <visual>
            <geometry>
                <mesh filename="package://owi535/meshes/wrist.dae" />
            </geometry>
        </visual>
        <inertial>
            <origin xyz="0 0 0" rpy="0 0 0" />
            <mass value="0.1" />
            <inertia
              ixx="1.0" ixy="0.0" ixz="0.0"
              iyy="1.0" iyz="0.0"
              izz="1.0" />
        </inertial>
    </link>
    <joint name="wrist_base" type="fixed">
        <parent link="wrist_motor" />
        <child link="wrist_base" />
        <origin xyz="-0.03 0 0" rpy="0 0 3.14" />
    </joint>
    <link name="back">
        <visual>
            <origin xyz="0 0 0" rpy="1.57 0 0" />
            <geometry>
                <mesh filename="package://owi535/meshes/back.dae" />
            </geometry>
        </visual>
        <inertial>
            <origin xyz="0 0 0" rpy="0 0 0" />
            <mass value="0.1" />
            <inertia
              ixx="1.0" ixy="0.0" ixz="0.0"
              iyy="1.0" iyz="0.0"
              izz="1.0" />
        </inertial>
    </link>
    <joint name="wrist" type="revolute">
        <parent link="wrist_base" />
        <child link="back" />
        <origin xyz="0 0 0" rpy="0 0 0" />
        <axis xyz="0 1.0 0" />
        <limit lower="-1.57" upper="1.57" effort="3" velocity="1.178465545" />
    </joint>
    <link name="shield">
        <visual>
            <origin xyz="-0.03 0 0" rpy="0 0 0" />
            <geometry>
                <mesh filename="package://owi535/meshes/shield.dae" />
            </geometry>
        </visual>
        <inertial>
            <origin xyz="0 0 0" rpy="0 0 0" />
            <mass value="0.1" />
            <inertia
              ixx="1.0" ixy="0.0" ixz="0.0"
              iyy="1.0" iyz="0.0"
              izz="1.0" />
        </inertial>
    </link>
    <joint name="shield_fix" type="fixed">
        <parent link="back" />
        <child link="shield" />
        <origin xyz="0 0 0" rpy="0 0 3.14" />
    </joint>

    <!--joint name="camera_joint" type="fixed">
      <origin xyz="0 0 0" rpy="0 0 3.14" />
      <parent link="back"/>
      <child link="camera_link"/>
    </joint>

    <link name="camera_link">
      <collision>
        <origin xyz="0 0 0" rpy="0 0 0"/>
        <geometry>
          <box size="15 10 5"/>
        </geometry>
      </collision>

      <visual>
        <origin xyz="0 0 0" rpy="0 0 0"/>
        <geometry>
          <box size="15 10 5"/>
        </geometry>
        <material name="red"/>
      </visual>

      <inertial>
        <mass value="1e-5" />
        <origin xyz="0 0 0" rpy="0 0 0"/>
        <inertia ixx="1e-6" ixy="0" ixz="0" iyy="1e-6" iyz="0" izz="1e-6" />
      </inertial>
    </link-->


    <link name="left_carpal">
        <visual>
            <origin xyz="0 0 0" rpy="0 0 0" />
            <geometry>
                <mesh filename="package://owi535/meshes/left_carpal.dae" />
            </geometry>
        </visual>
        <inertial>
            <mass value="1e-5" />
            <origin xyz="0 0 0" rpy="0 0 0"/>
            <inertia ixx="1e-6" ixy="0" ixz="0" iyy="1e-6" iyz="0" izz="1e-6" />
        </inertial>
    </link>
    <joint name="left_grip" type="revolute">
        <parent link="back" />
        <child link="left_carpal" />
        <origin xyz="0.0416 0.0135 0" rpy="3.14 0 0" />
        <axis xyz="0 0 1.0" />
        <limit lower="-1.20" upper="-0.08" effort="3" velocity="1.178465545" />
    </joint>
    <link name="left_phalange">
        <visual>
          <origin xyz="0 0 0" rpy="0 0 0" />
          <geometry>
              <mesh filename="package://owi535/meshes/phalange.dae" />
          </geometry>
          <inertial>
            <mass value="1e-5" />
            <origin xyz="0 0 0" rpy="0 0 0"/>
            <inertia ixx="1e-6" ixy="0" ixz="0" iyy="1e-6" iyz="0" izz="1e-6" />
          </inertial>
        </visual>
    </link>
    <joint name="left_ph" type="revolute">
        <mimic joint="left_grip" multiplier="1.0" />
        <parent link="back" />
        <child link="left_phalange" />
        <origin xyz="0.05856 0.0065 0" rpy="3.14 0 0" />
        <axis xyz="0 0 1.0" />
        <limit lower="-0.08" upper="1.20" effort="3" velocity="1.178465545" />
    </joint>
    <link name="left_finger">
        <visual>
            <origin xyz="0 0 0" rpy="0 0 0" />
            <geometry>
                <mesh filename="package://owi535/meshes/right_finger_tip.dae" />
            </geometry>
        </visual>
        <inertial>
            <mass value="1e-5" />
            <origin xyz="0 0 0" rpy="0 0 0"/>
            <inertia ixx="1e-6" ixy="0" ixz="0" iyy="1e-6" iyz="0" izz="1e-6" />
        </inertial>
    </link>
    <joint name="left_f" type="revolute">
        <mimic joint="left_grip" multiplier="-1.0" offset="3.14" />
        <parent link="left_phalange" />
        <child link="left_finger" />
        <origin xyz="0.0234 0 0" rpy="0 0 3.14" />
        <axis xyz="0 0 1.0" />
        <limit lower="-0.08" upper="1.20" effort="3" velocity="1.178465545" />
    </joint>
    <link name="right_carpal">
        <visual>
            <origin xyz="0 0 0" rpy="0 0 0" />
            <geometry>
                <mesh filename="package://owi535/meshes/right_carpal.dae" />
            </geometry>
        </visual>
        <inertial>
            <mass value="1e-5" />
            <origin xyz="0 0 0" rpy="0 0 0"/>
            <inertia ixx="1e-6" ixy="0" ixz="0" iyy="1e-6" iyz="0" izz="1e-6" />
        </inertial>
    </link>
    <joint name="right_grip" type="revolute">
        <mimic joint="left_grip" multiplier="-1.0" />
        <parent link="back" />
        <child link="right_carpal" />
        <origin xyz="0.0416 -0.0135 0" rpy="3.14 0 0" />
        <axis xyz="0 0 1.0" />
        <limit lower="-0.08" upper="1.20" effort="3" velocity="1.178465545" />
    </joint>
    <link name="right_phalange">
        <visual>
            <origin xyz="0 0 0" rpy="0 0 0" />
            <geometry>
                <mesh filename="package://owi535/meshes/phalange.dae" />
            </geometry>
        </visual>
        <inertial>
            <mass value="1e-5" />
            <origin xyz="0 0 0" rpy="0 0 0"/>
            <inertia ixx="1e-6" ixy="0" ixz="0" iyy="1e-6" iyz="0" izz="1e-6" />
        </inertial>
    </link>
    <joint name="right_ph" type="revolute">
        <mimic joint="left_grip" multiplier="-1.0" />
        <parent link="back" />
        <child link="right_phalange" />
        <origin xyz="0.05856 -0.0065 0" rpy="3.14 0 0" />
        <axis xyz="0 0 1.0" />
        <limit lower="-0.08" upper="1.20" effort="3" velocity="1.178465545" />
    </joint>
    <link name="right_finger">
        <visual>
            <origin xyz="0 0 0" rpy="0 0 0" />
            <geometry>
                <mesh filename="package://owi535/meshes/left_finger_tip.dae" />
            </geometry>
        </visual>
        <inertial>
            <mass value="1e-5" />
            <origin xyz="0 0 0" rpy="0 0 0"/>
            <inertia ixx="1e-6" ixy="0" ixz="0" iyy="1e-6" iyz="0" izz="1e-6" />
        </inertial>
    </link>
    <joint name="right_f" type="revolute">
        <mimic joint="right_grip" multiplier="-1.0" offset="3.14" />
        <parent link="right_phalange" />
        <child link="right_finger" />
        <origin xyz="0.0234 0 0" rpy="0 0 3.14" />
        <axis xyz="0 0 1.0" />
        <limit lower="-0.08" upper="1.20" effort="3" velocity="1.178465545" />
    </joint>
    
<transmission name="trans_rotationbase">
        <type>transmission_interface/SimpleTransmission</type>
        <joint name="rotationbase">
            <hardwareInterface>hardware_interface/EffortJointInterface</hardwareInterface>
        </joint>
        <actuator name="rotationbase_motor">
            <hardwareInterface>hardware_interface/EffortJointInterface</hardwareInterface>
            <mechanicalReduction>1</mechanicalReduction>
        </actuator>
    </transmission>
    <transmission name="trans_shoulder">
        <type>transmission_interface/SimpleTransmission</type>
        <joint name="shoulder">
            <hardwareInterface>hardware_interface/EffortJointInterface</hardwareInterface>
        </joint>
        <actuator name="shoulder_motor">
            <hardwareInterface>hardware_interface/EffortJointInterface</hardwareInterface>
            <mechanicalReduction>1</mechanicalReduction>
        </actuator>
    </transmission>
    <transmission name="trans_elbow">
        <type>transmission_interface/SimpleTransmission</type>
        <joint name="elbow">
            <hardwareInterface>hardware_interface/EffortJointInterface</hardwareInterface>
        </joint>
        <actuator name="elbow_motor">
            <hardwareInterface>hardware_interface/EffortJointInterface</hardwareInterface>
            <mechanicalReduction>1</mechanicalReduction>
        </actuator>
    </transmission>
    <transmission name="trans_wrist">
        <type>transmission_interface/SimpleTransmission</type>
        <joint name="wrist">
            <hardwareInterface>hardware_interface/EffortJointInterface</hardwareInterface>
        </joint>
        <actuator name="wrist_motor">
            <hardwareInterface>hardware_interface/EffortJointInterface</hardwareInterface>
            <mechanicalReduction>1</mechanicalReduction>
        </actuator>
    </transmission>
    <transmission name="trans_left_grip">
        <type>transmission_interface/SimpleTransmission</type>
        <joint name="left_grip">
            <hardwareInterface>hardware_interface/EffortJointInterface</hardwareInterface>
        </joint>
        <actuator name="left_grip_motor">
            <hardwareInterface>hardware_interface/EffortJointInterface</hardwareInterface>
            <mechanicalReduction>1</mechanicalReduction>
        </actuator>
    </transmission>
    <gazebo>
        <plugin name="gazebo_ros_control" filename="libgazebo_ros_control.so">
            <robotNamespace>/</robotNamespace>
        </plugin>
    </gazebo>
</robot>
